<?xml version='1.0'?>
<robot name="manipulator"
  xmlns:xacro="https://www.ros.org/wiki/xacro">
  <xacro:property name="width" value="0.1"/>
  <xacro:property name="height1" value="2" />
  <xacro:property name="height2" value="1" />
  <xacro:property name="height3" value="1" />
  <xacro:property name="axle_offset" value="0.05"/>

  <xacro:macro name="default_inertial" params="z_value i_value mass">
    <inertial>
      <origin xyz="0 0 ${z_value}" rpy="0 0 0"/>
      <mass value="${mass}" />
      <inertia ixx="${i_value}" ixy="0.0" ixz="0.0" iyy="${i_value}" iyz="0.0" izz="${i_value}" />
    </inertial>
  </xacro:macro>

  <gazebo>
    <static>False</static>
  </gazebo>

  <link name="base_link">
    <visual>
      <material name="red">
        <color rgba="0 1 1.0 1.0"/>
      </material>
      <origin xyz="0 0 1" rpy="0 0 0" />
      <geometry>
        <box size="${width} ${width} ${height1}"/>
      </geometry>
    </visual>
    <!-- Base collision, mass and inertia -->

    <collision>
      <origin xyz="0 0 0" rpy="0 0 0" />
      <geometry>
        <box size="${width} ${width} ${height1}"/>
      </geometry>
    </collision>
    <inertial>
      <origin xyz="0.0 0.0 1" rpy="0.0 0.0 0.0"/>
      <mass value="1"/>
      <inertia ixx="1" ixy="0.0" ixz="0.0" iyy="1.0" iyz="0.0" izz="1.0"/>
    </inertial>
    <xacro:default_inertial z_value="${height1/2}" i_value="1.0" mass="1"/>
  </link>

  <link name="world"/>

  <joint name="fixed" type="fixed">
    <parent link="world"/>
    <child link="base_link"/>
    <origin xyz="0.0 0.0 0.0" rpy="0.0 0.0 0.0"/>
         
  </joint>

  <!-- Joint between Base Link and Middle Link -->
  <joint name="joint_base_mid" type="continuous">
    <parent link="base_link"/>
    <child link="mid_link"/>
    <origin xyz="0 ${width} ${height1 - axle_offset}" rpy="0 0 0"/>
    <axis xyz="0 1 0"/>
  </joint>

  <link name="mid_link">
    <visual>
      <origin xyz="0 0 ${height2/2 - axle_offset}" rpy="0 0 0"/>
      <geometry>
        <box size="${width} ${width} ${height2}"/>
      </geometry>
      <material name="green"/>
    </visual>

    <collision>
      <origin xyz="0 0 ${height2/2 - axle_offset}" rpy="0 0 0"/>
      <geometry>
        <box size="${width} ${width} ${height2}"/>
      </geometry>
    </collision>

    <xacro:default_inertial z_value="${height2/2 - axle_offset}" i_value="1.0" mass="1"/>
  </link>

  <!-- Joint between Mid Link and Top link -->
  <joint name="joint_mid_top" type="continuous">
    <parent link="mid_link"/>
    <child link="top_link"/>
    <origin xyz="0 ${width} ${height2 - axle_offset*2}" rpy="0 0 0"/>
    <axis xyz="0 1 0"/>
  </joint>

  <!-- Top Link -->
  <link name="top_link">
    <visual>
      <origin xyz="0 0 ${height3/2 - axle_offset}" rpy="0 0 0"/>
      <geometry>
        <box size="${width} ${width} ${height3}"/>
      </geometry>
      <material name="blue"/>
    </visual>

    <collision>
      <origin xyz="0 0 ${height3/2 - axle_offset}" rpy="0 0 0"/>
      <geometry>
        <box size="${width} ${width} ${height3}"/>
      </geometry>
    </collision>

    <xacro:default_inertial z_value="${height3/2 - axle_offset}" i_value="1.0" mass="1"/>
  </link>

  <gazebo reference="base_link">
    <material>Gazebo/BlueGlow</material>
    <pose>0 0 3 0 0 0</pose>
  </gazebo>
  <!-- Middle Link -->
  <gazebo reference="mid_link">
    <mu1>0.2</mu1>
    <material>Gazebo/Green</material>
  </gazebo>

  <!-- Top Link -->
  <gazebo reference="top_link">
    <mu1>0.2</mu1>
    <mu2>0.2</mu2>
    <material>Gazebo/Blue</material>
  </gazebo>

</robot>